[2023-05-04 13:58:08,596] {taskinstance.py:1035} INFO - Dependencies all met for <TaskInstance: perform_predictions.predict.postgres.google_trends scheduled__2023-05-04T13:54:00+00:00 [queued]>
[2023-05-04 13:58:08,606] {taskinstance.py:1035} INFO - Dependencies all met for <TaskInstance: perform_predictions.predict.postgres.google_trends scheduled__2023-05-04T13:54:00+00:00 [queued]>
[2023-05-04 13:58:08,607] {taskinstance.py:1241} INFO - 
--------------------------------------------------------------------------------
[2023-05-04 13:58:08,608] {taskinstance.py:1242} INFO - Starting attempt 1 of 1
[2023-05-04 13:58:08,608] {taskinstance.py:1243} INFO - 
--------------------------------------------------------------------------------
[2023-05-04 13:58:08,617] {taskinstance.py:1262} INFO - Executing <Task(BashOperator): predict.postgres.google_trends> on 2023-05-04 13:54:00+00:00
[2023-05-04 13:58:08,621] {standard_task_runner.py:52} INFO - Started process 106 to run task
[2023-05-04 13:58:08,624] {standard_task_runner.py:76} INFO - Running: ['***', 'tasks', 'run', 'perform_predictions', 'predict.postgres.google_trends', 'scheduled__2023-05-04T13:54:00+00:00', '--job-id', '20', '--raw', '--subdir', 'DAGS_FOLDER/***_predictions_scheduler.py', '--cfg-path', '/tmp/tmpu8p4pqle', '--error-file', '/tmp/tmpxrh2mo3l']
[2023-05-04 13:58:08,626] {standard_task_runner.py:77} INFO - Job 20: Subtask predict.postgres.google_trends
[2023-05-04 13:58:08,667] {logging_mixin.py:109} INFO - Running <TaskInstance: perform_predictions.predict.postgres.google_trends scheduled__2023-05-04T13:54:00+00:00 [running]> on host c896eb598e2f
[2023-05-04 13:58:08,712] {taskinstance.py:1429} INFO - Exporting the following env vars:
AIRFLOW_CTX_DAG_EMAIL=***@example.com
AIRFLOW_CTX_DAG_OWNER=***
AIRFLOW_CTX_DAG_ID=perform_predictions
AIRFLOW_CTX_TASK_ID=predict.postgres.google_trends
AIRFLOW_CTX_EXECUTION_DATE=2023-05-04T13:54:00+00:00
AIRFLOW_CTX_DAG_RUN_ID=scheduled__2023-05-04T13:54:00+00:00
[2023-05-04 13:58:08,714] {subprocess.py:62} INFO - Tmp dir root location: 
 /tmp
[2023-05-04 13:58:08,716] {subprocess.py:74} INFO - Running command: ['bash', '-c', 'sleep 5 && /cmamp/src/load_validate_transform.py --source_table google_trends_data --target_table google_trends_predictions --topic DSLR']
[2023-05-04 13:58:08,724] {subprocess.py:85} INFO - Output:
[2023-05-04 13:58:15,612] {subprocess.py:89} INFO - Empty DataFrame
[2023-05-04 13:58:15,613] {subprocess.py:89} INFO - Columns: [Topic, Time, Frequency]
[2023-05-04 13:58:15,614] {subprocess.py:89} INFO - Index: []
[2023-05-04 13:58:15,615] {subprocess.py:89} INFO - Running all QA checks:
[2023-05-04 13:58:15,616] {subprocess.py:89} INFO - DenormalizedDatasetCheck: PASSED
[2023-05-04 13:58:15,617] {subprocess.py:89} INFO - Step 1: Converting to Dask Dataframe, Done
[2023-05-04 13:58:15,618] {subprocess.py:89} INFO - Step 2: Preprocessing before prediction, Done
[2023-05-04 13:58:15,619] {subprocess.py:89} INFO - Traceback (most recent call last):
[2023-05-04 13:58:15,620] {subprocess.py:89} INFO -   File "/cmamp/src/load_validate_transform.py", line 235, in <module>
[2023-05-04 13:58:15,620] {subprocess.py:89} INFO -     _main(_parse())
[2023-05-04 13:58:15,621] {subprocess.py:89} INFO -   File "/cmamp/src/load_validate_transform.py", line 226, in _main
[2023-05-04 13:58:15,622] {subprocess.py:89} INFO -     resampled_data = predict_data(data, topic)
[2023-05-04 13:58:15,623] {subprocess.py:89} INFO -   File "/cmamp/src/load_validate_transform.py", line 106, in predict_data
[2023-05-04 13:58:15,624] {subprocess.py:89} INFO -     start = processed_data.compute().index[-1] + pd.offsets.MonthBegin(1)
[2023-05-04 13:58:15,625] {subprocess.py:89} INFO -   File "/home/***/.local/lib/python3.7/site-packages/pandas/core/indexes/extension.py", line 279, in __getitem__
[2023-05-04 13:58:15,625] {subprocess.py:89} INFO -     result = self._data[key]
[2023-05-04 13:58:15,626] {subprocess.py:89} INFO -   File "/home/***/.local/lib/python3.7/site-packages/pandas/core/arrays/datetimelike.py", line 322, in __getitem__
[2023-05-04 13:58:15,627] {subprocess.py:89} INFO -     result = super().__getitem__(key)
[2023-05-04 13:58:15,628] {subprocess.py:89} INFO -   File "/home/***/.local/lib/python3.7/site-packages/pandas/core/arrays/_mixins.py", line 194, in __getitem__
[2023-05-04 13:58:15,629] {subprocess.py:89} INFO -     result = self._ndarray[key]
[2023-05-04 13:58:15,630] {subprocess.py:89} INFO - IndexError: index -1 is out of bounds for axis 0 with size 0
[2023-05-04 13:58:15,796] {subprocess.py:93} INFO - Command exited with return code 1
[2023-05-04 13:58:15,811] {taskinstance.py:1703} ERROR - Task failed with exception
Traceback (most recent call last):
  File "/home/airflow/.local/lib/python3.7/site-packages/airflow/models/taskinstance.py", line 1332, in _run_raw_task
    self._execute_task_with_callbacks(context)
  File "/home/airflow/.local/lib/python3.7/site-packages/airflow/models/taskinstance.py", line 1458, in _execute_task_with_callbacks
    result = self._execute_task(context, self.task)
  File "/home/airflow/.local/lib/python3.7/site-packages/airflow/models/taskinstance.py", line 1514, in _execute_task
    result = execute_callable(context=context)
  File "/home/airflow/.local/lib/python3.7/site-packages/airflow/operators/bash.py", line 188, in execute
    f'Bash command failed. The command returned a non-zero exit code {result.exit_code}.'
airflow.exceptions.AirflowException: Bash command failed. The command returned a non-zero exit code 1.
[2023-05-04 13:58:15,819] {taskinstance.py:1280} INFO - Marking task as FAILED. dag_id=perform_predictions, task_id=predict.postgres.google_trends, execution_date=20230504T135400, start_date=20230504T135808, end_date=20230504T135815
[2023-05-04 13:58:15,832] {standard_task_runner.py:91} ERROR - Failed to execute job 20 for task predict.postgres.google_trends
Traceback (most recent call last):
  File "/home/airflow/.local/lib/python3.7/site-packages/airflow/task/task_runner/standard_task_runner.py", line 85, in _start_by_fork
    args.func(args, dag=self.dag)
  File "/home/airflow/.local/lib/python3.7/site-packages/airflow/cli/cli_parser.py", line 48, in command
    return func(*args, **kwargs)
  File "/home/airflow/.local/lib/python3.7/site-packages/airflow/utils/cli.py", line 92, in wrapper
    return f(*args, **kwargs)
  File "/home/airflow/.local/lib/python3.7/site-packages/airflow/cli/commands/task_command.py", line 292, in task_run
    _run_task_by_selected_method(args, dag, ti)
  File "/home/airflow/.local/lib/python3.7/site-packages/airflow/cli/commands/task_command.py", line 107, in _run_task_by_selected_method
    _run_raw_task(args, ti)
  File "/home/airflow/.local/lib/python3.7/site-packages/airflow/cli/commands/task_command.py", line 184, in _run_raw_task
    error_file=args.error_file,
  File "/home/airflow/.local/lib/python3.7/site-packages/airflow/utils/session.py", line 70, in wrapper
    return func(*args, session=session, **kwargs)
  File "/home/airflow/.local/lib/python3.7/site-packages/airflow/models/taskinstance.py", line 1332, in _run_raw_task
    self._execute_task_with_callbacks(context)
  File "/home/airflow/.local/lib/python3.7/site-packages/airflow/models/taskinstance.py", line 1458, in _execute_task_with_callbacks
    result = self._execute_task(context, self.task)
  File "/home/airflow/.local/lib/python3.7/site-packages/airflow/models/taskinstance.py", line 1514, in _execute_task
    result = execute_callable(context=context)
  File "/home/airflow/.local/lib/python3.7/site-packages/airflow/operators/bash.py", line 188, in execute
    f'Bash command failed. The command returned a non-zero exit code {result.exit_code}.'
airflow.exceptions.AirflowException: Bash command failed. The command returned a non-zero exit code 1.
[2023-05-04 13:58:15,855] {local_task_job.py:154} INFO - Task exited with return code 1
[2023-05-04 13:58:15,878] {local_task_job.py:264} INFO - 0 downstream tasks scheduled from follow-on schedule check
