[2023-05-04 14:01:07,239] {taskinstance.py:1035} INFO - Dependencies all met for <TaskInstance: perform_predictions.predict.postgres.google_trends scheduled__2023-05-04T13:57:00+00:00 [queued]>
[2023-05-04 14:01:07,249] {taskinstance.py:1035} INFO - Dependencies all met for <TaskInstance: perform_predictions.predict.postgres.google_trends scheduled__2023-05-04T13:57:00+00:00 [queued]>
[2023-05-04 14:01:07,250] {taskinstance.py:1241} INFO - 
--------------------------------------------------------------------------------
[2023-05-04 14:01:07,251] {taskinstance.py:1242} INFO - Starting attempt 1 of 1
[2023-05-04 14:01:07,251] {taskinstance.py:1243} INFO - 
--------------------------------------------------------------------------------
[2023-05-04 14:01:07,261] {taskinstance.py:1262} INFO - Executing <Task(BashOperator): predict.postgres.google_trends> on 2023-05-04 13:57:00+00:00
[2023-05-04 14:01:07,264] {standard_task_runner.py:52} INFO - Started process 154 to run task
[2023-05-04 14:01:07,268] {standard_task_runner.py:76} INFO - Running: ['***', 'tasks', 'run', 'perform_predictions', 'predict.postgres.google_trends', 'scheduled__2023-05-04T13:57:00+00:00', '--job-id', '21', '--raw', '--subdir', 'DAGS_FOLDER/***_predictions_scheduler.py', '--cfg-path', '/tmp/tmpgdtdhb8t', '--error-file', '/tmp/tmpma175uhi']
[2023-05-04 14:01:07,269] {standard_task_runner.py:77} INFO - Job 21: Subtask predict.postgres.google_trends
[2023-05-04 14:01:07,312] {logging_mixin.py:109} INFO - Running <TaskInstance: perform_predictions.predict.postgres.google_trends scheduled__2023-05-04T13:57:00+00:00 [running]> on host c896eb598e2f
[2023-05-04 14:01:07,360] {taskinstance.py:1429} INFO - Exporting the following env vars:
AIRFLOW_CTX_DAG_EMAIL=***@example.com
AIRFLOW_CTX_DAG_OWNER=***
AIRFLOW_CTX_DAG_ID=perform_predictions
AIRFLOW_CTX_TASK_ID=predict.postgres.google_trends
AIRFLOW_CTX_EXECUTION_DATE=2023-05-04T13:57:00+00:00
AIRFLOW_CTX_DAG_RUN_ID=scheduled__2023-05-04T13:57:00+00:00
[2023-05-04 14:01:07,362] {subprocess.py:62} INFO - Tmp dir root location: 
 /tmp
[2023-05-04 14:01:07,364] {subprocess.py:74} INFO - Running command: ['bash', '-c', 'sleep 5 && /cmamp/src/load_validate_transform.py --source_table google_trends_data --target_table google_trends_predictions --topic DSLR']
[2023-05-04 14:01:07,371] {subprocess.py:85} INFO - Output:
[2023-05-04 14:01:14,195] {subprocess.py:89} INFO -     Topic      Time  Frequency
[2023-05-04 14:01:14,197] {subprocess.py:89} INFO - 0    dslr  Jan 2004        7.0
[2023-05-04 14:01:14,199] {subprocess.py:89} INFO - 1    dslr  Feb 2004       10.0
[2023-05-04 14:01:14,200] {subprocess.py:89} INFO - 2    dslr  Mar 2004        6.0
[2023-05-04 14:01:14,201] {subprocess.py:89} INFO - 3    dslr  Apr 2004        6.0
[2023-05-04 14:01:14,202] {subprocess.py:89} INFO - 4    dslr  May 2004        7.0
[2023-05-04 14:01:14,204] {subprocess.py:89} INFO - ..    ...       ...        ...
[2023-05-04 14:01:14,206] {subprocess.py:89} INFO - 227  dslr  Dec 2022       30.0
[2023-05-04 14:01:14,207] {subprocess.py:89} INFO - 228  dslr  Jan 2023       31.0
[2023-05-04 14:01:14,208] {subprocess.py:89} INFO - 229  dslr  Feb 2023       31.0
[2023-05-04 14:01:14,210] {subprocess.py:89} INFO - 230  dslr  Mar 2023       30.0
[2023-05-04 14:01:14,211] {subprocess.py:89} INFO - 231  dslr  Apr 2023       28.0
[2023-05-04 14:01:14,213] {subprocess.py:89} INFO - 
[2023-05-04 14:01:14,214] {subprocess.py:89} INFO - [232 rows x 3 columns]
[2023-05-04 14:01:14,215] {subprocess.py:89} INFO - Running all QA checks:
[2023-05-04 14:01:14,217] {subprocess.py:89} INFO - DenormalizedDatasetCheck: PASSED
[2023-05-04 14:01:14,218] {subprocess.py:89} INFO - Step 1: Converting to Dask Dataframe, Done
[2023-05-04 14:01:14,219] {subprocess.py:89} INFO - Step 2: Preprocessing before prediction, Done
[2023-05-04 14:01:14,220] {subprocess.py:89} INFO - Traceback (most recent call last):
[2023-05-04 14:01:14,221] {subprocess.py:89} INFO -   File "/cmamp/src/load_validate_transform.py", line 235, in <module>
[2023-05-04 14:01:14,222] {subprocess.py:89} INFO -     _main(_parse())
[2023-05-04 14:01:14,224] {subprocess.py:89} INFO -   File "/cmamp/src/load_validate_transform.py", line 226, in _main
[2023-05-04 14:01:14,226] {subprocess.py:89} INFO -     resampled_data = predict_data(data, topic)
[2023-05-04 14:01:14,227] {subprocess.py:89} INFO -   File "/cmamp/src/load_validate_transform.py", line 107, in predict_data
[2023-05-04 14:01:14,228] {subprocess.py:89} INFO -     end = processed_data.compute().index.values[-1] + pd.offsets.MonthBegin(12)
[2023-05-04 14:01:14,229] {subprocess.py:89} INFO - numpy.core._exceptions.UFuncTypeError: ufunc 'add' cannot use operands with types dtype('<M8[ns]') and dtype('O')
[2023-05-04 14:01:14,410] {subprocess.py:93} INFO - Command exited with return code 1
[2023-05-04 14:01:14,424] {taskinstance.py:1703} ERROR - Task failed with exception
Traceback (most recent call last):
  File "/home/airflow/.local/lib/python3.7/site-packages/airflow/models/taskinstance.py", line 1332, in _run_raw_task
    self._execute_task_with_callbacks(context)
  File "/home/airflow/.local/lib/python3.7/site-packages/airflow/models/taskinstance.py", line 1458, in _execute_task_with_callbacks
    result = self._execute_task(context, self.task)
  File "/home/airflow/.local/lib/python3.7/site-packages/airflow/models/taskinstance.py", line 1514, in _execute_task
    result = execute_callable(context=context)
  File "/home/airflow/.local/lib/python3.7/site-packages/airflow/operators/bash.py", line 188, in execute
    f'Bash command failed. The command returned a non-zero exit code {result.exit_code}.'
airflow.exceptions.AirflowException: Bash command failed. The command returned a non-zero exit code 1.
[2023-05-04 14:01:14,430] {taskinstance.py:1280} INFO - Marking task as FAILED. dag_id=perform_predictions, task_id=predict.postgres.google_trends, execution_date=20230504T135700, start_date=20230504T140107, end_date=20230504T140114
[2023-05-04 14:01:14,441] {standard_task_runner.py:91} ERROR - Failed to execute job 21 for task predict.postgres.google_trends
Traceback (most recent call last):
  File "/home/airflow/.local/lib/python3.7/site-packages/airflow/task/task_runner/standard_task_runner.py", line 85, in _start_by_fork
    args.func(args, dag=self.dag)
  File "/home/airflow/.local/lib/python3.7/site-packages/airflow/cli/cli_parser.py", line 48, in command
    return func(*args, **kwargs)
  File "/home/airflow/.local/lib/python3.7/site-packages/airflow/utils/cli.py", line 92, in wrapper
    return f(*args, **kwargs)
  File "/home/airflow/.local/lib/python3.7/site-packages/airflow/cli/commands/task_command.py", line 292, in task_run
    _run_task_by_selected_method(args, dag, ti)
  File "/home/airflow/.local/lib/python3.7/site-packages/airflow/cli/commands/task_command.py", line 107, in _run_task_by_selected_method
    _run_raw_task(args, ti)
  File "/home/airflow/.local/lib/python3.7/site-packages/airflow/cli/commands/task_command.py", line 184, in _run_raw_task
    error_file=args.error_file,
  File "/home/airflow/.local/lib/python3.7/site-packages/airflow/utils/session.py", line 70, in wrapper
    return func(*args, session=session, **kwargs)
  File "/home/airflow/.local/lib/python3.7/site-packages/airflow/models/taskinstance.py", line 1332, in _run_raw_task
    self._execute_task_with_callbacks(context)
  File "/home/airflow/.local/lib/python3.7/site-packages/airflow/models/taskinstance.py", line 1458, in _execute_task_with_callbacks
    result = self._execute_task(context, self.task)
  File "/home/airflow/.local/lib/python3.7/site-packages/airflow/models/taskinstance.py", line 1514, in _execute_task
    result = execute_callable(context=context)
  File "/home/airflow/.local/lib/python3.7/site-packages/airflow/operators/bash.py", line 188, in execute
    f'Bash command failed. The command returned a non-zero exit code {result.exit_code}.'
airflow.exceptions.AirflowException: Bash command failed. The command returned a non-zero exit code 1.
[2023-05-04 14:01:14,456] {local_task_job.py:154} INFO - Task exited with return code 1
[2023-05-04 14:01:14,478] {local_task_job.py:264} INFO - 0 downstream tasks scheduled from follow-on schedule check
