[2023-05-03 02:09:35,816] {taskinstance.py:1035} INFO - Dependencies all met for <TaskInstance: perform_predictions.predict.postgres.google_trends scheduled__2023-05-03T02:06:00+00:00 [queued]>
[2023-05-03 02:09:35,825] {taskinstance.py:1035} INFO - Dependencies all met for <TaskInstance: perform_predictions.predict.postgres.google_trends scheduled__2023-05-03T02:06:00+00:00 [queued]>
[2023-05-03 02:09:35,826] {taskinstance.py:1241} INFO - 
--------------------------------------------------------------------------------
[2023-05-03 02:09:35,827] {taskinstance.py:1242} INFO - Starting attempt 1 of 1
[2023-05-03 02:09:35,828] {taskinstance.py:1243} INFO - 
--------------------------------------------------------------------------------
[2023-05-03 02:09:35,837] {taskinstance.py:1262} INFO - Executing <Task(BashOperator): predict.postgres.google_trends> on 2023-05-03 02:06:00+00:00
[2023-05-03 02:09:35,841] {standard_task_runner.py:52} INFO - Started process 953 to run task
[2023-05-03 02:09:35,844] {standard_task_runner.py:76} INFO - Running: ['***', 'tasks', 'run', 'perform_predictions', 'predict.postgres.google_trends', 'scheduled__2023-05-03T02:06:00+00:00', '--job-id', '24', '--raw', '--subdir', 'DAGS_FOLDER/***_predictions_scheduler.py', '--cfg-path', '/tmp/tmpqn42sb58', '--error-file', '/tmp/tmpjxblj8rd']
[2023-05-03 02:09:35,846] {standard_task_runner.py:77} INFO - Job 24: Subtask predict.postgres.google_trends
[2023-05-03 02:09:35,888] {logging_mixin.py:109} INFO - Running <TaskInstance: perform_predictions.predict.postgres.google_trends scheduled__2023-05-03T02:06:00+00:00 [running]> on host adc748a128b1
[2023-05-03 02:09:35,934] {taskinstance.py:1429} INFO - Exporting the following env vars:
AIRFLOW_CTX_DAG_EMAIL=***@example.com
AIRFLOW_CTX_DAG_OWNER=***
AIRFLOW_CTX_DAG_ID=perform_predictions
AIRFLOW_CTX_TASK_ID=predict.postgres.google_trends
AIRFLOW_CTX_EXECUTION_DATE=2023-05-03T02:06:00+00:00
AIRFLOW_CTX_DAG_RUN_ID=scheduled__2023-05-03T02:06:00+00:00
[2023-05-03 02:09:35,936] {subprocess.py:62} INFO - Tmp dir root location: 
 /tmp
[2023-05-03 02:09:35,937] {subprocess.py:74} INFO - Running command: ['bash', '-c', 'sleep 5 && /cmamp/src/load_validate_transform.py --source_table google_trends_data --target_table google_trends_predictions --topic washing_machines']
[2023-05-03 02:09:35,945] {subprocess.py:85} INFO - Output:
[2023-05-03 02:09:41,404] {subprocess.py:89} INFO - Running all QA checks:
[2023-05-03 02:09:41,405] {subprocess.py:89} INFO - DenormalizedDatasetCheck: PASSED
[2023-05-03 02:09:41,406] {subprocess.py:89} INFO - RESAMPLING DATA
[2023-05-03 02:09:41,408] {subprocess.py:89} INFO - Traceback (most recent call last):
[2023-05-03 02:09:41,409] {subprocess.py:89} INFO -   File "/cmamp/src/load_validate_transform.py", line 118, in <module>
[2023-05-03 02:09:41,410] {subprocess.py:89} INFO -     _main(_parse())
[2023-05-03 02:09:41,411] {subprocess.py:89} INFO -   File "/cmamp/src/load_validate_transform.py", line 109, in _main
[2023-05-03 02:09:41,412] {subprocess.py:89} INFO -     resampled_data = _resample_data_to_5min(data)
[2023-05-03 02:09:41,413] {subprocess.py:89} INFO -   File "/cmamp/src/load_validate_transform.py", line 32, in _resample_data_to_5min
[2023-05-03 02:09:41,414] {subprocess.py:89} INFO -     data = pd.read_csv("../files/ipad.csv")
[2023-05-03 02:09:41,415] {subprocess.py:89} INFO -   File "/home/***/.local/lib/python3.7/site-packages/pandas/util/_decorators.py", line 311, in wrapper
[2023-05-03 02:09:41,416] {subprocess.py:89} INFO -     return func(*args, **kwargs)
[2023-05-03 02:09:41,416] {subprocess.py:89} INFO -   File "/home/***/.local/lib/python3.7/site-packages/pandas/io/parsers/readers.py", line 586, in read_csv
[2023-05-03 02:09:41,417] {subprocess.py:89} INFO -     return _read(filepath_or_buffer, kwds)
[2023-05-03 02:09:41,418] {subprocess.py:89} INFO -   File "/home/***/.local/lib/python3.7/site-packages/pandas/io/parsers/readers.py", line 482, in _read
[2023-05-03 02:09:41,419] {subprocess.py:89} INFO -     parser = TextFileReader(filepath_or_buffer, **kwds)
[2023-05-03 02:09:41,420] {subprocess.py:89} INFO -   File "/home/***/.local/lib/python3.7/site-packages/pandas/io/parsers/readers.py", line 811, in __init__
[2023-05-03 02:09:41,421] {subprocess.py:89} INFO -     self._engine = self._make_engine(self.engine)
[2023-05-03 02:09:41,422] {subprocess.py:89} INFO -   File "/home/***/.local/lib/python3.7/site-packages/pandas/io/parsers/readers.py", line 1040, in _make_engine
[2023-05-03 02:09:41,423] {subprocess.py:89} INFO -     return mapping[engine](self.f, **self.options)  # type: ignore[call-arg]
[2023-05-03 02:09:41,423] {subprocess.py:89} INFO -   File "/home/***/.local/lib/python3.7/site-packages/pandas/io/parsers/c_parser_wrapper.py", line 51, in __init__
[2023-05-03 02:09:41,424] {subprocess.py:89} INFO -     self._open_handles(src, kwds)
[2023-05-03 02:09:41,425] {subprocess.py:89} INFO -   File "/home/***/.local/lib/python3.7/site-packages/pandas/io/parsers/base_parser.py", line 229, in _open_handles
[2023-05-03 02:09:41,426] {subprocess.py:89} INFO -     errors=kwds.get("encoding_errors", "strict"),
[2023-05-03 02:09:41,427] {subprocess.py:89} INFO -   File "/home/***/.local/lib/python3.7/site-packages/pandas/io/common.py", line 707, in get_handle
[2023-05-03 02:09:41,428] {subprocess.py:89} INFO -     newline="",
[2023-05-03 02:09:41,429] {subprocess.py:89} INFO - FileNotFoundError: [Errno 2] No such file or directory: '../files/ipad.csv'
[2023-05-03 02:09:41,469] {subprocess.py:93} INFO - Command exited with return code 1
[2023-05-03 02:09:41,483] {taskinstance.py:1703} ERROR - Task failed with exception
Traceback (most recent call last):
  File "/home/airflow/.local/lib/python3.7/site-packages/airflow/models/taskinstance.py", line 1332, in _run_raw_task
    self._execute_task_with_callbacks(context)
  File "/home/airflow/.local/lib/python3.7/site-packages/airflow/models/taskinstance.py", line 1458, in _execute_task_with_callbacks
    result = self._execute_task(context, self.task)
  File "/home/airflow/.local/lib/python3.7/site-packages/airflow/models/taskinstance.py", line 1514, in _execute_task
    result = execute_callable(context=context)
  File "/home/airflow/.local/lib/python3.7/site-packages/airflow/operators/bash.py", line 188, in execute
    f'Bash command failed. The command returned a non-zero exit code {result.exit_code}.'
airflow.exceptions.AirflowException: Bash command failed. The command returned a non-zero exit code 1.
[2023-05-03 02:09:41,489] {taskinstance.py:1280} INFO - Marking task as FAILED. dag_id=perform_predictions, task_id=predict.postgres.google_trends, execution_date=20230503T020600, start_date=20230503T020935, end_date=20230503T020941
[2023-05-03 02:09:41,500] {standard_task_runner.py:91} ERROR - Failed to execute job 24 for task predict.postgres.google_trends
Traceback (most recent call last):
  File "/home/airflow/.local/lib/python3.7/site-packages/airflow/task/task_runner/standard_task_runner.py", line 85, in _start_by_fork
    args.func(args, dag=self.dag)
  File "/home/airflow/.local/lib/python3.7/site-packages/airflow/cli/cli_parser.py", line 48, in command
    return func(*args, **kwargs)
  File "/home/airflow/.local/lib/python3.7/site-packages/airflow/utils/cli.py", line 92, in wrapper
    return f(*args, **kwargs)
  File "/home/airflow/.local/lib/python3.7/site-packages/airflow/cli/commands/task_command.py", line 292, in task_run
    _run_task_by_selected_method(args, dag, ti)
  File "/home/airflow/.local/lib/python3.7/site-packages/airflow/cli/commands/task_command.py", line 107, in _run_task_by_selected_method
    _run_raw_task(args, ti)
  File "/home/airflow/.local/lib/python3.7/site-packages/airflow/cli/commands/task_command.py", line 184, in _run_raw_task
    error_file=args.error_file,
  File "/home/airflow/.local/lib/python3.7/site-packages/airflow/utils/session.py", line 70, in wrapper
    return func(*args, session=session, **kwargs)
  File "/home/airflow/.local/lib/python3.7/site-packages/airflow/models/taskinstance.py", line 1332, in _run_raw_task
    self._execute_task_with_callbacks(context)
  File "/home/airflow/.local/lib/python3.7/site-packages/airflow/models/taskinstance.py", line 1458, in _execute_task_with_callbacks
    result = self._execute_task(context, self.task)
  File "/home/airflow/.local/lib/python3.7/site-packages/airflow/models/taskinstance.py", line 1514, in _execute_task
    result = execute_callable(context=context)
  File "/home/airflow/.local/lib/python3.7/site-packages/airflow/operators/bash.py", line 188, in execute
    f'Bash command failed. The command returned a non-zero exit code {result.exit_code}.'
airflow.exceptions.AirflowException: Bash command failed. The command returned a non-zero exit code 1.
[2023-05-03 02:09:41,514] {local_task_job.py:154} INFO - Task exited with return code 1
[2023-05-03 02:09:41,538] {local_task_job.py:264} INFO - 0 downstream tasks scheduled from follow-on schedule check
