[2023-05-03T05:53:47.967+0000] {taskinstance.py:1090} INFO - Dependencies all met for dep_context=non-requeueable deps ti=<TaskInstance: dag_1min.dump_1m scheduled__2023-05-03T05:45:00+00:00 [queued]>
[2023-05-03T05:53:48.412+0000] {taskinstance.py:1090} INFO - Dependencies all met for dep_context=requeueable deps ti=<TaskInstance: dag_1min.dump_1m scheduled__2023-05-03T05:45:00+00:00 [queued]>
[2023-05-03T05:53:48.426+0000] {taskinstance.py:1288} INFO - 
--------------------------------------------------------------------------------
[2023-05-03T05:53:48.456+0000] {taskinstance.py:1289} INFO - Starting attempt 1 of 1
[2023-05-03T05:53:48.475+0000] {taskinstance.py:1290} INFO - 
--------------------------------------------------------------------------------
[2023-05-03T05:53:50.295+0000] {taskinstance.py:1309} INFO - Executing <Task(PythonOperator): dump_1m> on 2023-05-03 05:45:00+00:00
[2023-05-03T05:53:50.406+0000] {standard_task_runner.py:55} INFO - Started process 220 to run task
[2023-05-03T05:53:50.598+0000] {standard_task_runner.py:82} INFO - Running: ['***', 'tasks', 'run', 'dag_1min', 'dump_1m', 'scheduled__2023-05-03T05:45:00+00:00', '--job-id', '191', '--raw', '--subdir', 'DAGS_FOLDER/dag_1min.py', '--cfg-path', '/tmp/tmp95qkwcq0']
[2023-05-03T05:53:50.608+0000] {standard_task_runner.py:83} INFO - Job 191: Subtask dump_1m
[2023-05-03T05:53:52.548+0000] {task_command.py:389} INFO - Running <TaskInstance: dag_1min.dump_1m scheduled__2023-05-03T05:45:00+00:00 [running]> on host 7f3706140615
[2023-05-03T05:53:54.811+0000] {taskinstance.py:1518} INFO - Exporting the following env vars:
AIRFLOW_CTX_DAG_OWNER=coder2j
AIRFLOW_CTX_DAG_ID=dag_1min
AIRFLOW_CTX_TASK_ID=dump_1m
AIRFLOW_CTX_EXECUTION_DATE=2023-05-03T05:45:00+00:00
AIRFLOW_CTX_TRY_NUMBER=1
AIRFLOW_CTX_DAG_RUN_ID=scheduled__2023-05-03T05:45:00+00:00
[2023-05-03T05:54:02.713+0000] {logging_mixin.py:137} WARNING -   0%|          | 0/2 [00:00<?, ?it/s]
[2023-05-03T05:54:10.608+0000] {logging_mixin.py:137} INFO - [*********************100%***********************]  1 of 1 completed
[2023-05-03T05:54:12.801+0000] {logging_mixin.py:137} WARNING -  50%|#####     | 1/2 [00:10<00:10, 10.07s/it]
[2023-05-03T05:54:13.397+0000] {logging_mixin.py:137} INFO - [*********************100%***********************]  1 of 1 completed
[2023-05-03T05:54:14.964+0000] {logging_mixin.py:137} WARNING - 100%|##########| 2/2 [00:12<00:00,  5.42s/it]
[2023-05-03T05:54:14.975+0000] {logging_mixin.py:137} WARNING - 100%|##########| 2/2 [00:12<00:00,  6.12s/it]
[2023-05-03T05:54:15.005+0000] {logging_mixin.py:137} INFO - Index(['open', 'high', 'low', 'close', 'adj_close', 'volume', 'timestamp',
       'currency_pair', 'exchangetimezonename', 'timezone'],
      dtype='object')
[2023-05-03T05:54:15.221+0000] {download_yahoo.py:57} INFO - Downloaded data: 
	         open       high        low  ...  currency_pair  exchangetimezonename  timezone
0  16.723606  16.723606  16.723606  ...       AVAX-USD                   UTC       UTC
1  16.722237  16.722237  16.722237  ...       AVAX-USD                   UTC       UTC
2  16.710934  16.710934  16.710934  ...       AVAX-USD                   UTC       UTC
3  16.711157  16.711157  16.711157  ...       AVAX-USD                   UTC       UTC
4  16.712202  16.712202  16.712202  ...       AVAX-USD                   UTC       UTC

[5 rows x 10 columns]
[2023-05-03T05:54:15.343+0000] {taskinstance.py:1776} ERROR - Task failed with exception
Traceback (most recent call last):
  File "/home/airflow/.local/lib/python3.7/site-packages/sqlalchemy/engine/base.py", line 3361, in _wrap_pool_connect
    return fn()
  File "/home/airflow/.local/lib/python3.7/site-packages/sqlalchemy/pool/base.py", line 327, in connect
    return _ConnectionFairy._checkout(self)
  File "/home/airflow/.local/lib/python3.7/site-packages/sqlalchemy/pool/base.py", line 894, in _checkout
    fairy = _ConnectionRecord.checkout(pool)
  File "/home/airflow/.local/lib/python3.7/site-packages/sqlalchemy/pool/base.py", line 493, in checkout
    rec = pool._do_get()
  File "/home/airflow/.local/lib/python3.7/site-packages/sqlalchemy/pool/impl.py", line 146, in _do_get
    self._dec_overflow()
  File "/home/airflow/.local/lib/python3.7/site-packages/sqlalchemy/util/langhelpers.py", line 72, in __exit__
    with_traceback=exc_tb,
  File "/home/airflow/.local/lib/python3.7/site-packages/sqlalchemy/util/compat.py", line 211, in raise_
    raise exception
  File "/home/airflow/.local/lib/python3.7/site-packages/sqlalchemy/pool/impl.py", line 143, in _do_get
    return self._create_connection()
  File "/home/airflow/.local/lib/python3.7/site-packages/sqlalchemy/pool/base.py", line 273, in _create_connection
    return _ConnectionRecord(self)
  File "/home/airflow/.local/lib/python3.7/site-packages/sqlalchemy/pool/base.py", line 388, in __init__
    self.__connect()
  File "/home/airflow/.local/lib/python3.7/site-packages/sqlalchemy/pool/base.py", line 691, in __connect
    pool.logger.debug("Error on connect(): %s", e)
  File "/home/airflow/.local/lib/python3.7/site-packages/sqlalchemy/util/langhelpers.py", line 72, in __exit__
    with_traceback=exc_tb,
  File "/home/airflow/.local/lib/python3.7/site-packages/sqlalchemy/util/compat.py", line 211, in raise_
    raise exception
  File "/home/airflow/.local/lib/python3.7/site-packages/sqlalchemy/pool/base.py", line 686, in __connect
    self.dbapi_connection = connection = pool._invoke_creator(self)
  File "/home/airflow/.local/lib/python3.7/site-packages/sqlalchemy/engine/create.py", line 574, in connect
    return dialect.connect(*cargs, **cparams)
  File "/home/airflow/.local/lib/python3.7/site-packages/sqlalchemy/engine/default.py", line 598, in connect
    return self.dbapi.connect(*cargs, **cparams)
  File "/home/airflow/.local/lib/python3.7/site-packages/psycopg2/__init__.py", line 122, in connect
    conn = _connect(dsn, connection_factory=connection_factory, **kwasync)
psycopg2.OperationalError: connection to server at "host.docker.internal" (192.168.65.2), port 5432 failed: Connection refused
	Is the server running on that host and accepting TCP/IP connections?


The above exception was the direct cause of the following exception:

Traceback (most recent call last):
  File "/home/airflow/.local/lib/python3.7/site-packages/airflow/operators/python.py", line 175, in execute
    return_value = self.execute_callable()
  File "/home/airflow/.local/lib/python3.7/site-packages/airflow/operators/python.py", line 192, in execute_callable
    return self.python_callable(*self.op_args, **self.op_kwargs)
  File "/opt/airflow/dags/dag_1min.py", line 20, in dump_1m
    dump_latest_data('yahoo_yfinance_spot_downloaded_1min','1m')
  File "/code/Latest_Data.py", line 46, in dump_latest_data
    p.to_sql(tablename, engine, if_exists='append',index=False)
  File "/home/airflow/.local/lib/python3.7/site-packages/pandas/core/generic.py", line 2882, in to_sql
    method=method,
  File "/home/airflow/.local/lib/python3.7/site-packages/pandas/io/sql.py", line 728, in to_sql
    **engine_kwargs,
  File "/home/airflow/.local/lib/python3.7/site-packages/pandas/io/sql.py", line 1758, in to_sql
    dtype=dtype,
  File "/home/airflow/.local/lib/python3.7/site-packages/pandas/io/sql.py", line 1650, in prep_table
    table.create()
  File "/home/airflow/.local/lib/python3.7/site-packages/pandas/io/sql.py", line 856, in create
    if self.exists():
  File "/home/airflow/.local/lib/python3.7/site-packages/pandas/io/sql.py", line 840, in exists
    return self.pd_sql.has_table(self.name, self.schema)
  File "/home/airflow/.local/lib/python3.7/site-packages/pandas/io/sql.py", line 1783, in has_table
    insp = sa.inspect(self.connectable)
  File "/home/airflow/.local/lib/python3.7/site-packages/sqlalchemy/inspection.py", line 64, in inspect
    ret = reg(subject)
  File "/home/airflow/.local/lib/python3.7/site-packages/sqlalchemy/engine/reflection.py", line 182, in _engine_insp
    return Inspector._construct(Inspector._init_engine, bind)
  File "/home/airflow/.local/lib/python3.7/site-packages/sqlalchemy/engine/reflection.py", line 117, in _construct
    init(self, bind)
  File "/home/airflow/.local/lib/python3.7/site-packages/sqlalchemy/engine/reflection.py", line 128, in _init_engine
    engine.connect().close()
  File "/home/airflow/.local/lib/python3.7/site-packages/sqlalchemy/engine/base.py", line 3315, in connect
    return self._connection_cls(self, close_with_result=close_with_result)
  File "/home/airflow/.local/lib/python3.7/site-packages/sqlalchemy/engine/base.py", line 96, in __init__
    else engine.raw_connection()
  File "/home/airflow/.local/lib/python3.7/site-packages/sqlalchemy/engine/base.py", line 3394, in raw_connection
    return self._wrap_pool_connect(self.pool.connect, _connection)
  File "/home/airflow/.local/lib/python3.7/site-packages/sqlalchemy/engine/base.py", line 3365, in _wrap_pool_connect
    e, dialect, self
  File "/home/airflow/.local/lib/python3.7/site-packages/sqlalchemy/engine/base.py", line 2199, in _handle_dbapi_exception_noconnection
    sqlalchemy_exception, with_traceback=exc_info[2], from_=e
  File "/home/airflow/.local/lib/python3.7/site-packages/sqlalchemy/util/compat.py", line 211, in raise_
    raise exception
  File "/home/airflow/.local/lib/python3.7/site-packages/sqlalchemy/engine/base.py", line 3361, in _wrap_pool_connect
    return fn()
  File "/home/airflow/.local/lib/python3.7/site-packages/sqlalchemy/pool/base.py", line 327, in connect
    return _ConnectionFairy._checkout(self)
  File "/home/airflow/.local/lib/python3.7/site-packages/sqlalchemy/pool/base.py", line 894, in _checkout
    fairy = _ConnectionRecord.checkout(pool)
  File "/home/airflow/.local/lib/python3.7/site-packages/sqlalchemy/pool/base.py", line 493, in checkout
    rec = pool._do_get()
  File "/home/airflow/.local/lib/python3.7/site-packages/sqlalchemy/pool/impl.py", line 146, in _do_get
    self._dec_overflow()
  File "/home/airflow/.local/lib/python3.7/site-packages/sqlalchemy/util/langhelpers.py", line 72, in __exit__
    with_traceback=exc_tb,
  File "/home/airflow/.local/lib/python3.7/site-packages/sqlalchemy/util/compat.py", line 211, in raise_
    raise exception
  File "/home/airflow/.local/lib/python3.7/site-packages/sqlalchemy/pool/impl.py", line 143, in _do_get
    return self._create_connection()
  File "/home/airflow/.local/lib/python3.7/site-packages/sqlalchemy/pool/base.py", line 273, in _create_connection
    return _ConnectionRecord(self)
  File "/home/airflow/.local/lib/python3.7/site-packages/sqlalchemy/pool/base.py", line 388, in __init__
    self.__connect()
  File "/home/airflow/.local/lib/python3.7/site-packages/sqlalchemy/pool/base.py", line 691, in __connect
    pool.logger.debug("Error on connect(): %s", e)
  File "/home/airflow/.local/lib/python3.7/site-packages/sqlalchemy/util/langhelpers.py", line 72, in __exit__
    with_traceback=exc_tb,
  File "/home/airflow/.local/lib/python3.7/site-packages/sqlalchemy/util/compat.py", line 211, in raise_
    raise exception
  File "/home/airflow/.local/lib/python3.7/site-packages/sqlalchemy/pool/base.py", line 686, in __connect
    self.dbapi_connection = connection = pool._invoke_creator(self)
  File "/home/airflow/.local/lib/python3.7/site-packages/sqlalchemy/engine/create.py", line 574, in connect
    return dialect.connect(*cargs, **cparams)
  File "/home/airflow/.local/lib/python3.7/site-packages/sqlalchemy/engine/default.py", line 598, in connect
    return self.dbapi.connect(*cargs, **cparams)
  File "/home/airflow/.local/lib/python3.7/site-packages/psycopg2/__init__.py", line 122, in connect
    conn = _connect(dsn, connection_factory=connection_factory, **kwasync)
sqlalchemy.exc.OperationalError: (psycopg2.OperationalError) connection to server at "host.docker.internal" (192.168.65.2), port 5432 failed: Connection refused
	Is the server running on that host and accepting TCP/IP connections?

(Background on this error at: https://sqlalche.me/e/14/e3q8)
[2023-05-03T05:54:15.441+0000] {taskinstance.py:1332} INFO - Marking task as FAILED. dag_id=dag_1min, task_id=dump_1m, execution_date=20230503T054500, start_date=20230503T055348, end_date=20230503T055415
[2023-05-03T05:54:15.522+0000] {standard_task_runner.py:105} ERROR - Failed to execute job 191 for task dump_1m ((psycopg2.OperationalError) connection to server at "host.docker.internal" (192.168.65.2), port 5432 failed: Connection refused
	Is the server running on that host and accepting TCP/IP connections?

(Background on this error at: https://sqlalche.me/e/14/e3q8); 220)
[2023-05-03T05:54:15.616+0000] {local_task_job.py:212} INFO - Task exited with return code 1
[2023-05-03T05:54:15.769+0000] {taskinstance.py:2596} INFO - 0 downstream tasks scheduled from follow-on schedule check
