[2023-05-03 02:12:01,781] {taskinstance.py:1035} INFO - Dependencies all met for <TaskInstance: perform_predictions.predict.postgres.google_trends scheduled__2023-05-03T02:10:00+00:00 [queued]>
[2023-05-03 02:12:01,792] {taskinstance.py:1035} INFO - Dependencies all met for <TaskInstance: perform_predictions.predict.postgres.google_trends scheduled__2023-05-03T02:10:00+00:00 [queued]>
[2023-05-03 02:12:01,793] {taskinstance.py:1241} INFO - 
--------------------------------------------------------------------------------
[2023-05-03 02:12:01,794] {taskinstance.py:1242} INFO - Starting attempt 1 of 1
[2023-05-03 02:12:01,795] {taskinstance.py:1243} INFO - 
--------------------------------------------------------------------------------
[2023-05-03 02:12:01,804] {taskinstance.py:1262} INFO - Executing <Task(BashOperator): predict.postgres.google_trends> on 2023-05-03 02:10:00+00:00
[2023-05-03 02:12:01,808] {standard_task_runner.py:52} INFO - Started process 1019 to run task
[2023-05-03 02:12:01,812] {standard_task_runner.py:76} INFO - Running: ['***', 'tasks', 'run', 'perform_predictions', 'predict.postgres.google_trends', 'scheduled__2023-05-03T02:10:00+00:00', '--job-id', '27', '--raw', '--subdir', 'DAGS_FOLDER/***_predictions_scheduler.py', '--cfg-path', '/tmp/tmpxcmil7a9', '--error-file', '/tmp/tmpm46fvfgk']
[2023-05-03 02:12:01,813] {standard_task_runner.py:77} INFO - Job 27: Subtask predict.postgres.google_trends
[2023-05-03 02:12:01,858] {logging_mixin.py:109} INFO - Running <TaskInstance: perform_predictions.predict.postgres.google_trends scheduled__2023-05-03T02:10:00+00:00 [running]> on host adc748a128b1
[2023-05-03 02:12:01,907] {taskinstance.py:1429} INFO - Exporting the following env vars:
AIRFLOW_CTX_DAG_EMAIL=***@example.com
AIRFLOW_CTX_DAG_OWNER=***
AIRFLOW_CTX_DAG_ID=perform_predictions
AIRFLOW_CTX_TASK_ID=predict.postgres.google_trends
AIRFLOW_CTX_EXECUTION_DATE=2023-05-03T02:10:00+00:00
AIRFLOW_CTX_DAG_RUN_ID=scheduled__2023-05-03T02:10:00+00:00
[2023-05-03 02:12:01,909] {subprocess.py:62} INFO - Tmp dir root location: 
 /tmp
[2023-05-03 02:12:01,911] {subprocess.py:74} INFO - Running command: ['bash', '-c', 'sleep 5 && /cmamp/src/load_validate_transform.py --source_table google_trends_data --target_table google_trends_predictions --topic washing_machines']
[2023-05-03 02:12:01,919] {subprocess.py:85} INFO - Output:
[2023-05-03 02:12:07,436] {subprocess.py:89} INFO - Running all QA checks:
[2023-05-03 02:12:07,438] {subprocess.py:89} INFO - DenormalizedDatasetCheck: PASSED
[2023-05-03 02:12:07,440] {subprocess.py:89} INFO - RESAMPLING DATA
[2023-05-03 02:12:07,441] {subprocess.py:89} INFO -                 Topic       Time  Record Type  Frequency
[2023-05-03 02:12:07,442] {subprocess.py:89} INFO - 0    washing machines 2004-01-01         data      100.0
[2023-05-03 02:12:07,443] {subprocess.py:89} INFO - 1    washing machines 2004-02-01         data       95.0
[2023-05-03 02:12:07,444] {subprocess.py:89} INFO - 2    washing machines 2004-03-01         data       87.0
[2023-05-03 02:12:07,445] {subprocess.py:89} INFO - 3    washing machines 2004-04-01         data       79.0
[2023-05-03 02:12:07,446] {subprocess.py:89} INFO - 4    washing machines 2004-05-01         data       82.0
[2023-05-03 02:12:07,447] {subprocess.py:89} INFO - ..                ...        ...          ...        ...
[2023-05-03 02:12:07,448] {subprocess.py:89} INFO - 227  washing machines 2022-12-01  predictions       25.0
[2023-05-03 02:12:07,449] {subprocess.py:89} INFO - 228  washing machines 2023-01-01  predictions       25.0
[2023-05-03 02:12:07,450] {subprocess.py:89} INFO - 229  washing machines 2023-02-01  predictions       24.0
[2023-05-03 02:12:07,451] {subprocess.py:89} INFO - 230  washing machines 2023-03-01  predictions       23.0
[2023-05-03 02:12:07,452] {subprocess.py:89} INFO - 231  washing machines 2023-04-01  predictions       24.0
[2023-05-03 02:12:07,453] {subprocess.py:89} INFO - 
[2023-05-03 02:12:07,454] {subprocess.py:89} INFO - [232 rows x 4 columns]
[2023-05-03 02:12:07,455] {subprocess.py:89} INFO - Traceback (most recent call last):
[2023-05-03 02:12:07,458] {subprocess.py:89} INFO -   File "/cmamp/src/load_validate_transform.py", line 117, in <module>
[2023-05-03 02:12:07,459] {subprocess.py:89} INFO -     _main(_parse())
[2023-05-03 02:12:07,460] {subprocess.py:89} INFO -   File "/cmamp/src/load_validate_transform.py", line 113, in _main
[2023-05-03 02:12:07,461] {subprocess.py:89} INFO -     db_saver.save(resampled_data, args.target_table, args.topic)
[2023-05-03 02:12:07,462] {subprocess.py:89} INFO -   File "/cmamp/src/db.py", line 94, in save
[2023-05-03 02:12:07,463] {subprocess.py:89} INFO -     query = self._create_delete_query(topic)
[2023-05-03 02:12:07,464] {subprocess.py:89} INFO - TypeError: _create_delete_query() missing 1 required positional argument: 'topic'
[2023-05-03 02:12:07,521] {subprocess.py:93} INFO - Command exited with return code 1
[2023-05-03 02:12:07,539] {taskinstance.py:1703} ERROR - Task failed with exception
Traceback (most recent call last):
  File "/home/airflow/.local/lib/python3.7/site-packages/airflow/models/taskinstance.py", line 1332, in _run_raw_task
    self._execute_task_with_callbacks(context)
  File "/home/airflow/.local/lib/python3.7/site-packages/airflow/models/taskinstance.py", line 1458, in _execute_task_with_callbacks
    result = self._execute_task(context, self.task)
  File "/home/airflow/.local/lib/python3.7/site-packages/airflow/models/taskinstance.py", line 1514, in _execute_task
    result = execute_callable(context=context)
  File "/home/airflow/.local/lib/python3.7/site-packages/airflow/operators/bash.py", line 188, in execute
    f'Bash command failed. The command returned a non-zero exit code {result.exit_code}.'
airflow.exceptions.AirflowException: Bash command failed. The command returned a non-zero exit code 1.
[2023-05-03 02:12:07,547] {taskinstance.py:1280} INFO - Marking task as FAILED. dag_id=perform_predictions, task_id=predict.postgres.google_trends, execution_date=20230503T021000, start_date=20230503T021201, end_date=20230503T021207
[2023-05-03 02:12:07,563] {standard_task_runner.py:91} ERROR - Failed to execute job 27 for task predict.postgres.google_trends
Traceback (most recent call last):
  File "/home/airflow/.local/lib/python3.7/site-packages/airflow/task/task_runner/standard_task_runner.py", line 85, in _start_by_fork
    args.func(args, dag=self.dag)
  File "/home/airflow/.local/lib/python3.7/site-packages/airflow/cli/cli_parser.py", line 48, in command
    return func(*args, **kwargs)
  File "/home/airflow/.local/lib/python3.7/site-packages/airflow/utils/cli.py", line 92, in wrapper
    return f(*args, **kwargs)
  File "/home/airflow/.local/lib/python3.7/site-packages/airflow/cli/commands/task_command.py", line 292, in task_run
    _run_task_by_selected_method(args, dag, ti)
  File "/home/airflow/.local/lib/python3.7/site-packages/airflow/cli/commands/task_command.py", line 107, in _run_task_by_selected_method
    _run_raw_task(args, ti)
  File "/home/airflow/.local/lib/python3.7/site-packages/airflow/cli/commands/task_command.py", line 184, in _run_raw_task
    error_file=args.error_file,
  File "/home/airflow/.local/lib/python3.7/site-packages/airflow/utils/session.py", line 70, in wrapper
    return func(*args, session=session, **kwargs)
  File "/home/airflow/.local/lib/python3.7/site-packages/airflow/models/taskinstance.py", line 1332, in _run_raw_task
    self._execute_task_with_callbacks(context)
  File "/home/airflow/.local/lib/python3.7/site-packages/airflow/models/taskinstance.py", line 1458, in _execute_task_with_callbacks
    result = self._execute_task(context, self.task)
  File "/home/airflow/.local/lib/python3.7/site-packages/airflow/models/taskinstance.py", line 1514, in _execute_task
    result = execute_callable(context=context)
  File "/home/airflow/.local/lib/python3.7/site-packages/airflow/operators/bash.py", line 188, in execute
    f'Bash command failed. The command returned a non-zero exit code {result.exit_code}.'
airflow.exceptions.AirflowException: Bash command failed. The command returned a non-zero exit code 1.
[2023-05-03 02:12:07,587] {local_task_job.py:154} INFO - Task exited with return code 1
[2023-05-03 02:12:07,621] {local_task_job.py:264} INFO - 0 downstream tasks scheduled from follow-on schedule check
