[2023-05-03 01:10:26,652] {taskinstance.py:1035} INFO - Dependencies all met for <TaskInstance: download_historical_postgres.download.historical.postgres.google_trends scheduled__2023-05-03T00:00:00+00:00 [queued]>
[2023-05-03 01:10:26,661] {taskinstance.py:1035} INFO - Dependencies all met for <TaskInstance: download_historical_postgres.download.historical.postgres.google_trends scheduled__2023-05-03T00:00:00+00:00 [queued]>
[2023-05-03 01:10:26,662] {taskinstance.py:1241} INFO - 
--------------------------------------------------------------------------------
[2023-05-03 01:10:26,663] {taskinstance.py:1242} INFO - Starting attempt 1 of 1
[2023-05-03 01:10:26,664] {taskinstance.py:1243} INFO - 
--------------------------------------------------------------------------------
[2023-05-03 01:10:26,673] {taskinstance.py:1262} INFO - Executing <Task(BashOperator): download.historical.postgres.google_trends> on 2023-05-03 00:00:00+00:00
[2023-05-03 01:10:26,676] {standard_task_runner.py:52} INFO - Started process 374 to run task
[2023-05-03 01:10:26,680] {standard_task_runner.py:76} INFO - Running: ['***', 'tasks', 'run', 'download_historical_postgres', 'download.historical.postgres.google_trends', 'scheduled__2023-05-03T00:00:00+00:00', '--job-id', '17', '--raw', '--subdir', 'DAGS_FOLDER/download_historical_postgres_google_trends.py', '--cfg-path', '/tmp/tmpucteboae', '--error-file', '/tmp/tmp1kebi_9z']
[2023-05-03 01:10:26,681] {standard_task_runner.py:77} INFO - Job 17: Subtask download.historical.postgres.google_trends
[2023-05-03 01:10:26,722] {logging_mixin.py:109} INFO - Running <TaskInstance: download_historical_postgres.download.historical.postgres.google_trends scheduled__2023-05-03T00:00:00+00:00 [running]> on host adc748a128b1
[2023-05-03 01:10:26,765] {taskinstance.py:1429} INFO - Exporting the following env vars:
AIRFLOW_CTX_DAG_EMAIL=***@example.com
AIRFLOW_CTX_DAG_OWNER=***
AIRFLOW_CTX_DAG_ID=download_historical_postgres
AIRFLOW_CTX_TASK_ID=download.historical.postgres.google_trends
AIRFLOW_CTX_EXECUTION_DATE=2023-05-03T00:00:00+00:00
AIRFLOW_CTX_DAG_RUN_ID=scheduled__2023-05-03T00:00:00+00:00
[2023-05-03 01:10:26,767] {subprocess.py:62} INFO - Tmp dir root location: 
 /tmp
[2023-05-03 01:10:26,768] {subprocess.py:74} INFO - Running command: ['bash', '-c', 'sleep 5 && /cmamp/src/download_to_db.py --target_table google_trends_data --use_api True --real_time_data False']
[2023-05-03 01:10:26,776] {subprocess.py:85} INFO - Output:
[2023-05-03 01:10:32,153] {subprocess.py:89} INFO - usage: download_to_db.py [-h] --topic TOPIC --source_table SOURCE_TABLE
[2023-05-03 01:10:32,154] {subprocess.py:89} INFO -                          --target_table TARGET_TABLE
[2023-05-03 01:10:32,154] {subprocess.py:89} INFO - download_to_db.py: error: the following arguments are required: --topic, --source_table
[2023-05-03 01:10:32,196] {subprocess.py:93} INFO - Command exited with return code 2
[2023-05-03 01:10:32,212] {taskinstance.py:1703} ERROR - Task failed with exception
Traceback (most recent call last):
  File "/home/airflow/.local/lib/python3.7/site-packages/airflow/models/taskinstance.py", line 1332, in _run_raw_task
    self._execute_task_with_callbacks(context)
  File "/home/airflow/.local/lib/python3.7/site-packages/airflow/models/taskinstance.py", line 1458, in _execute_task_with_callbacks
    result = self._execute_task(context, self.task)
  File "/home/airflow/.local/lib/python3.7/site-packages/airflow/models/taskinstance.py", line 1514, in _execute_task
    result = execute_callable(context=context)
  File "/home/airflow/.local/lib/python3.7/site-packages/airflow/operators/bash.py", line 188, in execute
    f'Bash command failed. The command returned a non-zero exit code {result.exit_code}.'
airflow.exceptions.AirflowException: Bash command failed. The command returned a non-zero exit code 2.
[2023-05-03 01:10:32,220] {taskinstance.py:1280} INFO - Marking task as FAILED. dag_id=download_historical_postgres, task_id=download.historical.postgres.google_trends, execution_date=20230503T000000, start_date=20230503T011026, end_date=20230503T011032
[2023-05-03 01:10:32,244] {standard_task_runner.py:91} ERROR - Failed to execute job 17 for task download.historical.postgres.google_trends
Traceback (most recent call last):
  File "/home/airflow/.local/lib/python3.7/site-packages/airflow/task/task_runner/standard_task_runner.py", line 85, in _start_by_fork
    args.func(args, dag=self.dag)
  File "/home/airflow/.local/lib/python3.7/site-packages/airflow/cli/cli_parser.py", line 48, in command
    return func(*args, **kwargs)
  File "/home/airflow/.local/lib/python3.7/site-packages/airflow/utils/cli.py", line 92, in wrapper
    return f(*args, **kwargs)
  File "/home/airflow/.local/lib/python3.7/site-packages/airflow/cli/commands/task_command.py", line 292, in task_run
    _run_task_by_selected_method(args, dag, ti)
  File "/home/airflow/.local/lib/python3.7/site-packages/airflow/cli/commands/task_command.py", line 107, in _run_task_by_selected_method
    _run_raw_task(args, ti)
  File "/home/airflow/.local/lib/python3.7/site-packages/airflow/cli/commands/task_command.py", line 184, in _run_raw_task
    error_file=args.error_file,
  File "/home/airflow/.local/lib/python3.7/site-packages/airflow/utils/session.py", line 70, in wrapper
    return func(*args, session=session, **kwargs)
  File "/home/airflow/.local/lib/python3.7/site-packages/airflow/models/taskinstance.py", line 1332, in _run_raw_task
    self._execute_task_with_callbacks(context)
  File "/home/airflow/.local/lib/python3.7/site-packages/airflow/models/taskinstance.py", line 1458, in _execute_task_with_callbacks
    result = self._execute_task(context, self.task)
  File "/home/airflow/.local/lib/python3.7/site-packages/airflow/models/taskinstance.py", line 1514, in _execute_task
    result = execute_callable(context=context)
  File "/home/airflow/.local/lib/python3.7/site-packages/airflow/operators/bash.py", line 188, in execute
    f'Bash command failed. The command returned a non-zero exit code {result.exit_code}.'
airflow.exceptions.AirflowException: Bash command failed. The command returned a non-zero exit code 2.
[2023-05-03 01:10:32,265] {local_task_job.py:154} INFO - Task exited with return code 1
[2023-05-03 01:10:32,288] {local_task_job.py:264} INFO - 0 downstream tasks scheduled from follow-on schedule check
