[2023-05-03 00:52:01,598] {taskinstance.py:1035} INFO - Dependencies all met for <TaskInstance: perform_predictions.predict.postgres.google_trends scheduled__2023-05-03T00:50:00+00:00 [queued]>
[2023-05-03 00:52:01,606] {taskinstance.py:1035} INFO - Dependencies all met for <TaskInstance: perform_predictions.predict.postgres.google_trends scheduled__2023-05-03T00:50:00+00:00 [queued]>
[2023-05-03 00:52:01,607] {taskinstance.py:1241} INFO - 
--------------------------------------------------------------------------------
[2023-05-03 00:52:01,608] {taskinstance.py:1242} INFO - Starting attempt 1 of 1
[2023-05-03 00:52:01,609] {taskinstance.py:1243} INFO - 
--------------------------------------------------------------------------------
[2023-05-03 00:52:01,618] {taskinstance.py:1262} INFO - Executing <Task(BashOperator): predict.postgres.google_trends> on 2023-05-03 00:50:00+00:00
[2023-05-03 00:52:01,621] {standard_task_runner.py:52} INFO - Started process 145 to run task
[2023-05-03 00:52:01,625] {standard_task_runner.py:76} INFO - Running: ['***', 'tasks', 'run', 'perform_predictions', 'predict.postgres.google_trends', 'scheduled__2023-05-03T00:50:00+00:00', '--job-id', '5', '--raw', '--subdir', 'DAGS_FOLDER/***_predictions_scheduler.py', '--cfg-path', '/tmp/tmpp_ux82q_', '--error-file', '/tmp/tmpzgervzh1']
[2023-05-03 00:52:01,626] {standard_task_runner.py:77} INFO - Job 5: Subtask predict.postgres.google_trends
[2023-05-03 00:52:01,666] {logging_mixin.py:109} INFO - Running <TaskInstance: perform_predictions.predict.postgres.google_trends scheduled__2023-05-03T00:50:00+00:00 [running]> on host adc748a128b1
[2023-05-03 00:52:01,709] {taskinstance.py:1429} INFO - Exporting the following env vars:
AIRFLOW_CTX_DAG_EMAIL=***@example.com
AIRFLOW_CTX_DAG_OWNER=***
AIRFLOW_CTX_DAG_ID=perform_predictions
AIRFLOW_CTX_TASK_ID=predict.postgres.google_trends
AIRFLOW_CTX_EXECUTION_DATE=2023-05-03T00:50:00+00:00
AIRFLOW_CTX_DAG_RUN_ID=scheduled__2023-05-03T00:50:00+00:00
[2023-05-03 00:52:01,711] {subprocess.py:62} INFO - Tmp dir root location: 
 /tmp
[2023-05-03 00:52:01,712] {subprocess.py:74} INFO - Running command: ['bash', '-c', "chmod +x /cmamp/src/ && sleep 5 && /cmamp/src/perform_ml_predictions.py --source_table 'google_trends_data' --target_table 'google_trends_predictions' --topic 'washing_machine'"]
[2023-05-03 00:52:01,720] {subprocess.py:85} INFO - Output:
[2023-05-03 00:52:06,733] {subprocess.py:89} INFO - bash: /cmamp/src/perform_ml_predictions.py: Permission denied
[2023-05-03 00:52:06,734] {subprocess.py:93} INFO - Command exited with return code 126
[2023-05-03 00:52:06,750] {taskinstance.py:1703} ERROR - Task failed with exception
Traceback (most recent call last):
  File "/home/airflow/.local/lib/python3.7/site-packages/airflow/models/taskinstance.py", line 1332, in _run_raw_task
    self._execute_task_with_callbacks(context)
  File "/home/airflow/.local/lib/python3.7/site-packages/airflow/models/taskinstance.py", line 1458, in _execute_task_with_callbacks
    result = self._execute_task(context, self.task)
  File "/home/airflow/.local/lib/python3.7/site-packages/airflow/models/taskinstance.py", line 1514, in _execute_task
    result = execute_callable(context=context)
  File "/home/airflow/.local/lib/python3.7/site-packages/airflow/operators/bash.py", line 188, in execute
    f'Bash command failed. The command returned a non-zero exit code {result.exit_code}.'
airflow.exceptions.AirflowException: Bash command failed. The command returned a non-zero exit code 126.
[2023-05-03 00:52:06,757] {taskinstance.py:1280} INFO - Marking task as FAILED. dag_id=perform_predictions, task_id=predict.postgres.google_trends, execution_date=20230503T005000, start_date=20230503T005201, end_date=20230503T005206
[2023-05-03 00:52:06,769] {standard_task_runner.py:91} ERROR - Failed to execute job 5 for task predict.postgres.google_trends
Traceback (most recent call last):
  File "/home/airflow/.local/lib/python3.7/site-packages/airflow/task/task_runner/standard_task_runner.py", line 85, in _start_by_fork
    args.func(args, dag=self.dag)
  File "/home/airflow/.local/lib/python3.7/site-packages/airflow/cli/cli_parser.py", line 48, in command
    return func(*args, **kwargs)
  File "/home/airflow/.local/lib/python3.7/site-packages/airflow/utils/cli.py", line 92, in wrapper
    return f(*args, **kwargs)
  File "/home/airflow/.local/lib/python3.7/site-packages/airflow/cli/commands/task_command.py", line 292, in task_run
    _run_task_by_selected_method(args, dag, ti)
  File "/home/airflow/.local/lib/python3.7/site-packages/airflow/cli/commands/task_command.py", line 107, in _run_task_by_selected_method
    _run_raw_task(args, ti)
  File "/home/airflow/.local/lib/python3.7/site-packages/airflow/cli/commands/task_command.py", line 184, in _run_raw_task
    error_file=args.error_file,
  File "/home/airflow/.local/lib/python3.7/site-packages/airflow/utils/session.py", line 70, in wrapper
    return func(*args, session=session, **kwargs)
  File "/home/airflow/.local/lib/python3.7/site-packages/airflow/models/taskinstance.py", line 1332, in _run_raw_task
    self._execute_task_with_callbacks(context)
  File "/home/airflow/.local/lib/python3.7/site-packages/airflow/models/taskinstance.py", line 1458, in _execute_task_with_callbacks
    result = self._execute_task(context, self.task)
  File "/home/airflow/.local/lib/python3.7/site-packages/airflow/models/taskinstance.py", line 1514, in _execute_task
    result = execute_callable(context=context)
  File "/home/airflow/.local/lib/python3.7/site-packages/airflow/operators/bash.py", line 188, in execute
    f'Bash command failed. The command returned a non-zero exit code {result.exit_code}.'
airflow.exceptions.AirflowException: Bash command failed. The command returned a non-zero exit code 126.
[2023-05-03 00:52:06,799] {local_task_job.py:154} INFO - Task exited with return code 1
[2023-05-03 00:52:06,824] {local_task_job.py:264} INFO - 0 downstream tasks scheduled from follow-on schedule check
