[2023-05-04 13:48:01,544] {taskinstance.py:1035} INFO - Dependencies all met for <TaskInstance: perform_predictions.predict.postgres.google_trends scheduled__2023-05-04T13:42:00+00:00 [queued]>
[2023-05-04 13:48:01,552] {taskinstance.py:1035} INFO - Dependencies all met for <TaskInstance: perform_predictions.predict.postgres.google_trends scheduled__2023-05-04T13:42:00+00:00 [queued]>
[2023-05-04 13:48:01,554] {taskinstance.py:1241} INFO - 
--------------------------------------------------------------------------------
[2023-05-04 13:48:01,555] {taskinstance.py:1242} INFO - Starting attempt 1 of 1
[2023-05-04 13:48:01,556] {taskinstance.py:1243} INFO - 
--------------------------------------------------------------------------------
[2023-05-04 13:48:01,565] {taskinstance.py:1262} INFO - Executing <Task(BashOperator): predict.postgres.google_trends> on 2023-05-04 13:42:00+00:00
[2023-05-04 13:48:01,569] {standard_task_runner.py:52} INFO - Started process 494 to run task
[2023-05-04 13:48:01,573] {standard_task_runner.py:76} INFO - Running: ['***', 'tasks', 'run', 'perform_predictions', 'predict.postgres.google_trends', 'scheduled__2023-05-04T13:42:00+00:00', '--job-id', '17', '--raw', '--subdir', 'DAGS_FOLDER/***_predictions_scheduler.py', '--cfg-path', '/tmp/tmp94_7kzsn', '--error-file', '/tmp/tmpolbupehe']
[2023-05-04 13:48:01,574] {standard_task_runner.py:77} INFO - Job 17: Subtask predict.postgres.google_trends
[2023-05-04 13:48:01,616] {logging_mixin.py:109} INFO - Running <TaskInstance: perform_predictions.predict.postgres.google_trends scheduled__2023-05-04T13:42:00+00:00 [running]> on host 7d6ed9fdc9c5
[2023-05-04 13:48:01,660] {taskinstance.py:1429} INFO - Exporting the following env vars:
AIRFLOW_CTX_DAG_EMAIL=***@example.com
AIRFLOW_CTX_DAG_OWNER=***
AIRFLOW_CTX_DAG_ID=perform_predictions
AIRFLOW_CTX_TASK_ID=predict.postgres.google_trends
AIRFLOW_CTX_EXECUTION_DATE=2023-05-04T13:42:00+00:00
AIRFLOW_CTX_DAG_RUN_ID=scheduled__2023-05-04T13:42:00+00:00
[2023-05-04 13:48:01,662] {subprocess.py:62} INFO - Tmp dir root location: 
 /tmp
[2023-05-04 13:48:01,664] {subprocess.py:74} INFO - Running command: ['bash', '-c', 'sleep 5 && /cmamp/src/load_validate_transform.py --source_table google_trends_data --target_table google_trends_predictions --topic DSLR']
[2023-05-04 13:48:01,671] {subprocess.py:85} INFO - Output:
[2023-05-04 13:48:07,621] {subprocess.py:89} INFO - Traceback (most recent call last):
[2023-05-04 13:48:07,622] {subprocess.py:89} INFO -   File "/cmamp/src/load_validate_transform.py", line 15, in <module>
[2023-05-04 13:48:07,623] {subprocess.py:89} INFO -     from pmdarima.arima import auto_arima
[2023-05-04 13:48:07,624] {subprocess.py:89} INFO - ModuleNotFoundError: No module named 'pmdarima'
[2023-05-04 13:48:07,679] {subprocess.py:93} INFO - Command exited with return code 1
[2023-05-04 13:48:07,694] {taskinstance.py:1703} ERROR - Task failed with exception
Traceback (most recent call last):
  File "/home/airflow/.local/lib/python3.7/site-packages/airflow/models/taskinstance.py", line 1332, in _run_raw_task
    self._execute_task_with_callbacks(context)
  File "/home/airflow/.local/lib/python3.7/site-packages/airflow/models/taskinstance.py", line 1458, in _execute_task_with_callbacks
    result = self._execute_task(context, self.task)
  File "/home/airflow/.local/lib/python3.7/site-packages/airflow/models/taskinstance.py", line 1514, in _execute_task
    result = execute_callable(context=context)
  File "/home/airflow/.local/lib/python3.7/site-packages/airflow/operators/bash.py", line 188, in execute
    f'Bash command failed. The command returned a non-zero exit code {result.exit_code}.'
airflow.exceptions.AirflowException: Bash command failed. The command returned a non-zero exit code 1.
[2023-05-04 13:48:07,701] {taskinstance.py:1280} INFO - Marking task as FAILED. dag_id=perform_predictions, task_id=predict.postgres.google_trends, execution_date=20230504T134200, start_date=20230504T134801, end_date=20230504T134807
[2023-05-04 13:48:07,715] {standard_task_runner.py:91} ERROR - Failed to execute job 17 for task predict.postgres.google_trends
Traceback (most recent call last):
  File "/home/airflow/.local/lib/python3.7/site-packages/airflow/task/task_runner/standard_task_runner.py", line 85, in _start_by_fork
    args.func(args, dag=self.dag)
  File "/home/airflow/.local/lib/python3.7/site-packages/airflow/cli/cli_parser.py", line 48, in command
    return func(*args, **kwargs)
  File "/home/airflow/.local/lib/python3.7/site-packages/airflow/utils/cli.py", line 92, in wrapper
    return f(*args, **kwargs)
  File "/home/airflow/.local/lib/python3.7/site-packages/airflow/cli/commands/task_command.py", line 292, in task_run
    _run_task_by_selected_method(args, dag, ti)
  File "/home/airflow/.local/lib/python3.7/site-packages/airflow/cli/commands/task_command.py", line 107, in _run_task_by_selected_method
    _run_raw_task(args, ti)
  File "/home/airflow/.local/lib/python3.7/site-packages/airflow/cli/commands/task_command.py", line 184, in _run_raw_task
    error_file=args.error_file,
  File "/home/airflow/.local/lib/python3.7/site-packages/airflow/utils/session.py", line 70, in wrapper
    return func(*args, session=session, **kwargs)
  File "/home/airflow/.local/lib/python3.7/site-packages/airflow/models/taskinstance.py", line 1332, in _run_raw_task
    self._execute_task_with_callbacks(context)
  File "/home/airflow/.local/lib/python3.7/site-packages/airflow/models/taskinstance.py", line 1458, in _execute_task_with_callbacks
    result = self._execute_task(context, self.task)
  File "/home/airflow/.local/lib/python3.7/site-packages/airflow/models/taskinstance.py", line 1514, in _execute_task
    result = execute_callable(context=context)
  File "/home/airflow/.local/lib/python3.7/site-packages/airflow/operators/bash.py", line 188, in execute
    f'Bash command failed. The command returned a non-zero exit code {result.exit_code}.'
airflow.exceptions.AirflowException: Bash command failed. The command returned a non-zero exit code 1.
[2023-05-04 13:48:07,763] {local_task_job.py:154} INFO - Task exited with return code 1
[2023-05-04 13:48:07,792] {local_task_job.py:264} INFO - 0 downstream tasks scheduled from follow-on schedule check
