[2023-05-03 00:34:02,066] {taskinstance.py:1035} INFO - Dependencies all met for <TaskInstance: perform_predictions.predict.postgres.google_trends scheduled__2023-05-03T00:32:00+00:00 [queued]>
[2023-05-03 00:34:02,074] {taskinstance.py:1035} INFO - Dependencies all met for <TaskInstance: perform_predictions.predict.postgres.google_trends scheduled__2023-05-03T00:32:00+00:00 [queued]>
[2023-05-03 00:34:02,075] {taskinstance.py:1241} INFO - 
--------------------------------------------------------------------------------
[2023-05-03 00:34:02,076] {taskinstance.py:1242} INFO - Starting attempt 1 of 1
[2023-05-03 00:34:02,077] {taskinstance.py:1243} INFO - 
--------------------------------------------------------------------------------
[2023-05-03 00:34:02,085] {taskinstance.py:1262} INFO - Executing <Task(BashOperator): predict.postgres.google_trends> on 2023-05-03 00:32:00+00:00
[2023-05-03 00:34:02,089] {standard_task_runner.py:52} INFO - Started process 1824 to run task
[2023-05-03 00:34:02,093] {standard_task_runner.py:76} INFO - Running: ['***', 'tasks', 'run', 'perform_predictions', 'predict.postgres.google_trends', 'scheduled__2023-05-03T00:32:00+00:00', '--job-id', '38', '--raw', '--subdir', 'DAGS_FOLDER/***_predictions_scheduler.py', '--cfg-path', '/tmp/tmpxfyscdec', '--error-file', '/tmp/tmpbg3d7jnq']
[2023-05-03 00:34:02,094] {standard_task_runner.py:77} INFO - Job 38: Subtask predict.postgres.google_trends
[2023-05-03 00:34:02,134] {logging_mixin.py:109} INFO - Running <TaskInstance: perform_predictions.predict.postgres.google_trends scheduled__2023-05-03T00:32:00+00:00 [running]> on host a509f10d64ee
[2023-05-03 00:34:02,177] {taskinstance.py:1429} INFO - Exporting the following env vars:
AIRFLOW_CTX_DAG_EMAIL=***@example.com
AIRFLOW_CTX_DAG_OWNER=***
AIRFLOW_CTX_DAG_ID=perform_predictions
AIRFLOW_CTX_TASK_ID=predict.postgres.google_trends
AIRFLOW_CTX_EXECUTION_DATE=2023-05-03T00:32:00+00:00
AIRFLOW_CTX_DAG_RUN_ID=scheduled__2023-05-03T00:32:00+00:00
[2023-05-03 00:34:02,179] {subprocess.py:62} INFO - Tmp dir root location: 
 /tmp
[2023-05-03 00:34:02,180] {subprocess.py:74} INFO - Running command: ['bash', '-c', "sleep 5 && /cmamp/src/perform_ml_predictions.py --source_table 'google_trends_data' --target_table 'google_trends_predictions' --topic 'washing_machine'"]
[2023-05-03 00:34:02,188] {subprocess.py:85} INFO - Output:
[2023-05-03 00:34:07,197] {subprocess.py:89} INFO - bash: /cmamp/src/perform_ml_predictions.py: /usr/bin/env: bad interpreter: Permission denied
[2023-05-03 00:34:07,199] {subprocess.py:93} INFO - Command exited with return code 126
[2023-05-03 00:34:07,214] {taskinstance.py:1703} ERROR - Task failed with exception
Traceback (most recent call last):
  File "/home/airflow/.local/lib/python3.7/site-packages/airflow/models/taskinstance.py", line 1332, in _run_raw_task
    self._execute_task_with_callbacks(context)
  File "/home/airflow/.local/lib/python3.7/site-packages/airflow/models/taskinstance.py", line 1458, in _execute_task_with_callbacks
    result = self._execute_task(context, self.task)
  File "/home/airflow/.local/lib/python3.7/site-packages/airflow/models/taskinstance.py", line 1514, in _execute_task
    result = execute_callable(context=context)
  File "/home/airflow/.local/lib/python3.7/site-packages/airflow/operators/bash.py", line 188, in execute
    f'Bash command failed. The command returned a non-zero exit code {result.exit_code}.'
airflow.exceptions.AirflowException: Bash command failed. The command returned a non-zero exit code 126.
[2023-05-03 00:34:07,222] {taskinstance.py:1280} INFO - Marking task as FAILED. dag_id=perform_predictions, task_id=predict.postgres.google_trends, execution_date=20230503T003200, start_date=20230503T003402, end_date=20230503T003407
[2023-05-03 00:34:07,235] {standard_task_runner.py:91} ERROR - Failed to execute job 38 for task predict.postgres.google_trends
Traceback (most recent call last):
  File "/home/airflow/.local/lib/python3.7/site-packages/airflow/task/task_runner/standard_task_runner.py", line 85, in _start_by_fork
    args.func(args, dag=self.dag)
  File "/home/airflow/.local/lib/python3.7/site-packages/airflow/cli/cli_parser.py", line 48, in command
    return func(*args, **kwargs)
  File "/home/airflow/.local/lib/python3.7/site-packages/airflow/utils/cli.py", line 92, in wrapper
    return f(*args, **kwargs)
  File "/home/airflow/.local/lib/python3.7/site-packages/airflow/cli/commands/task_command.py", line 292, in task_run
    _run_task_by_selected_method(args, dag, ti)
  File "/home/airflow/.local/lib/python3.7/site-packages/airflow/cli/commands/task_command.py", line 107, in _run_task_by_selected_method
    _run_raw_task(args, ti)
  File "/home/airflow/.local/lib/python3.7/site-packages/airflow/cli/commands/task_command.py", line 184, in _run_raw_task
    error_file=args.error_file,
  File "/home/airflow/.local/lib/python3.7/site-packages/airflow/utils/session.py", line 70, in wrapper
    return func(*args, session=session, **kwargs)
  File "/home/airflow/.local/lib/python3.7/site-packages/airflow/models/taskinstance.py", line 1332, in _run_raw_task
    self._execute_task_with_callbacks(context)
  File "/home/airflow/.local/lib/python3.7/site-packages/airflow/models/taskinstance.py", line 1458, in _execute_task_with_callbacks
    result = self._execute_task(context, self.task)
  File "/home/airflow/.local/lib/python3.7/site-packages/airflow/models/taskinstance.py", line 1514, in _execute_task
    result = execute_callable(context=context)
  File "/home/airflow/.local/lib/python3.7/site-packages/airflow/operators/bash.py", line 188, in execute
    f'Bash command failed. The command returned a non-zero exit code {result.exit_code}.'
airflow.exceptions.AirflowException: Bash command failed. The command returned a non-zero exit code 126.
[2023-05-03 00:34:07,277] {local_task_job.py:154} INFO - Task exited with return code 1
[2023-05-03 00:34:07,302] {local_task_job.py:264} INFO - 0 downstream tasks scheduled from follow-on schedule check
