[2023-05-03 01:00:02,311] {taskinstance.py:1035} INFO - Dependencies all met for <TaskInstance: perform_predictions.predict.postgres.google_trends scheduled__2023-05-03T00:58:00+00:00 [queued]>
[2023-05-03 01:00:02,319] {taskinstance.py:1035} INFO - Dependencies all met for <TaskInstance: perform_predictions.predict.postgres.google_trends scheduled__2023-05-03T00:58:00+00:00 [queued]>
[2023-05-03 01:00:02,320] {taskinstance.py:1241} INFO - 
--------------------------------------------------------------------------------
[2023-05-03 01:00:02,321] {taskinstance.py:1242} INFO - Starting attempt 1 of 1
[2023-05-03 01:00:02,322] {taskinstance.py:1243} INFO - 
--------------------------------------------------------------------------------
[2023-05-03 01:00:02,331] {taskinstance.py:1262} INFO - Executing <Task(BashOperator): predict.postgres.google_trends> on 2023-05-03 00:58:00+00:00
[2023-05-03 01:00:02,334] {standard_task_runner.py:52} INFO - Started process 250 to run task
[2023-05-03 01:00:02,338] {standard_task_runner.py:76} INFO - Running: ['***', 'tasks', 'run', 'perform_predictions', 'predict.postgres.google_trends', 'scheduled__2023-05-03T00:58:00+00:00', '--job-id', '10', '--raw', '--subdir', 'DAGS_FOLDER/***_predictions_scheduler.py', '--cfg-path', '/tmp/tmpxp9ghq9l', '--error-file', '/tmp/tmpvlh298i3']
[2023-05-03 01:00:02,339] {standard_task_runner.py:77} INFO - Job 10: Subtask predict.postgres.google_trends
[2023-05-03 01:00:02,378] {logging_mixin.py:109} INFO - Running <TaskInstance: perform_predictions.predict.postgres.google_trends scheduled__2023-05-03T00:58:00+00:00 [running]> on host adc748a128b1
[2023-05-03 01:00:02,419] {taskinstance.py:1429} INFO - Exporting the following env vars:
AIRFLOW_CTX_DAG_EMAIL=***@example.com
AIRFLOW_CTX_DAG_OWNER=***
AIRFLOW_CTX_DAG_ID=perform_predictions
AIRFLOW_CTX_TASK_ID=predict.postgres.google_trends
AIRFLOW_CTX_EXECUTION_DATE=2023-05-03T00:58:00+00:00
AIRFLOW_CTX_DAG_RUN_ID=scheduled__2023-05-03T00:58:00+00:00
[2023-05-03 01:00:02,421] {subprocess.py:62} INFO - Tmp dir root location: 
 /tmp
[2023-05-03 01:00:02,422] {subprocess.py:74} INFO - Running command: ['bash', '-c', 'sleep 5 && /cmamp/src/perform_ml_predictions.py --source_table google_trends_data --target_table google_trends_predictions --topic washing_machines']
[2023-05-03 01:00:02,430] {subprocess.py:85} INFO - Output:
[2023-05-03 01:00:07,437] {subprocess.py:89} INFO - bash: /cmamp/src/perform_ml_predictions.py: Permission denied
[2023-05-03 01:00:07,439] {subprocess.py:93} INFO - Command exited with return code 126
[2023-05-03 01:00:07,454] {taskinstance.py:1703} ERROR - Task failed with exception
Traceback (most recent call last):
  File "/home/airflow/.local/lib/python3.7/site-packages/airflow/models/taskinstance.py", line 1332, in _run_raw_task
    self._execute_task_with_callbacks(context)
  File "/home/airflow/.local/lib/python3.7/site-packages/airflow/models/taskinstance.py", line 1458, in _execute_task_with_callbacks
    result = self._execute_task(context, self.task)
  File "/home/airflow/.local/lib/python3.7/site-packages/airflow/models/taskinstance.py", line 1514, in _execute_task
    result = execute_callable(context=context)
  File "/home/airflow/.local/lib/python3.7/site-packages/airflow/operators/bash.py", line 188, in execute
    f'Bash command failed. The command returned a non-zero exit code {result.exit_code}.'
airflow.exceptions.AirflowException: Bash command failed. The command returned a non-zero exit code 126.
[2023-05-03 01:00:07,461] {taskinstance.py:1280} INFO - Marking task as FAILED. dag_id=perform_predictions, task_id=predict.postgres.google_trends, execution_date=20230503T005800, start_date=20230503T010002, end_date=20230503T010007
[2023-05-03 01:00:07,472] {standard_task_runner.py:91} ERROR - Failed to execute job 10 for task predict.postgres.google_trends
Traceback (most recent call last):
  File "/home/airflow/.local/lib/python3.7/site-packages/airflow/task/task_runner/standard_task_runner.py", line 85, in _start_by_fork
    args.func(args, dag=self.dag)
  File "/home/airflow/.local/lib/python3.7/site-packages/airflow/cli/cli_parser.py", line 48, in command
    return func(*args, **kwargs)
  File "/home/airflow/.local/lib/python3.7/site-packages/airflow/utils/cli.py", line 92, in wrapper
    return f(*args, **kwargs)
  File "/home/airflow/.local/lib/python3.7/site-packages/airflow/cli/commands/task_command.py", line 292, in task_run
    _run_task_by_selected_method(args, dag, ti)
  File "/home/airflow/.local/lib/python3.7/site-packages/airflow/cli/commands/task_command.py", line 107, in _run_task_by_selected_method
    _run_raw_task(args, ti)
  File "/home/airflow/.local/lib/python3.7/site-packages/airflow/cli/commands/task_command.py", line 184, in _run_raw_task
    error_file=args.error_file,
  File "/home/airflow/.local/lib/python3.7/site-packages/airflow/utils/session.py", line 70, in wrapper
    return func(*args, session=session, **kwargs)
  File "/home/airflow/.local/lib/python3.7/site-packages/airflow/models/taskinstance.py", line 1332, in _run_raw_task
    self._execute_task_with_callbacks(context)
  File "/home/airflow/.local/lib/python3.7/site-packages/airflow/models/taskinstance.py", line 1458, in _execute_task_with_callbacks
    result = self._execute_task(context, self.task)
  File "/home/airflow/.local/lib/python3.7/site-packages/airflow/models/taskinstance.py", line 1514, in _execute_task
    result = execute_callable(context=context)
  File "/home/airflow/.local/lib/python3.7/site-packages/airflow/operators/bash.py", line 188, in execute
    f'Bash command failed. The command returned a non-zero exit code {result.exit_code}.'
airflow.exceptions.AirflowException: Bash command failed. The command returned a non-zero exit code 126.
[2023-05-03 01:00:07,487] {local_task_job.py:154} INFO - Task exited with return code 1
[2023-05-03 01:00:07,509] {local_task_job.py:264} INFO - 0 downstream tasks scheduled from follow-on schedule check
